Workbook

Sheet Dashboard
B3: Active Customers | G3: MRR | K3: ARR | O3: Churn | S3: Retention | W3: NRR
C4: =INDEX(KPI_Engine!B:B, MATCH(MAX(KPI_Engine!A:A), KPI_Engine!A:A, 0)) -> 5 | G4: =INDEX(KPI_Engine!C:C, MATCH(MAX(KPI_Engine!A:A), KPI_Engine!A:A, 0)) -> 257 | K4: =INDEX(KPI_Engine!D:D, MATCH(MAX(KPI_Engine!A:A), KPI_Engine!A:A, 0)) -> 3084 | O4: =INDEX(KPI_Engine!F:F, MATCH(MAX(KPI_Engine!A:A), KPI_Engine!A:A, 0)) -> 0.44444444 | S4: =INDEX(KPI_Engine!G:G, MATCH(MAX(KPI_Engine!A:A), KPI_Engine!A:A, 0)) -> 0.55555556 | W4: =INDEX(KPI_Engine!J:J, MATCH(MAX(KPI_Engine!A:A), KPI_Engine!A:A, 0)) -> 0.97348485

Sheet KPI_Engine
A1: Month | B1: Active_Customers | C1: MRR | D1: ARR | E1: ARPU | F1: Churn_Rate | G1: Retention_Rate | H1: Revenue_Churn | I1: GRR | J1: NRR | K1: Repeat_Customers | L1: Repeat_Purchase_Rate | M1: Column1
A2: =EOMONTH(MIN(tbl_Invoices[Invoice_Date]), 0) -> 44227 | B2: {=_xlfn.LET( _xlpm.m, EOMONTH(A2,0), _xlpm.cust, _xlfn.UNIQUE(_xlfn._xlws.FILTER(tbl_Invoices[Customer_ID], tbl_Invoices[Month]=_xlpm.m)), ROWS(_xlpm.cust) )} -> 9 | C2: =IFERROR(SUMIFS(tbl_Invoices[Amount], tbl_Invoices[Month], A2, tbl_Invoices[Active_Flag], 1), 0) -> 251 | D2: =IFERROR(C2*12, 0) -> 3012 | E2: =IFERROR(C2/B2, 0) -> 27.888889 | F2: =IF(ROW()=2,0,IF(B1=0,0,MAX(B1-B2,0)/B1)) -> 0 | G2: =IF(ROW()=2,1,1-F2) -> 1 | H2: =IF(ROW()=2,0,MAX(C1-C2,0)) -> 0 | I2: =IF(ROW()=2,1,IF(C1=0,1,1-H2/C1)) -> 1 | J2: =IF(ROW()=2,1,IF(C1=0,1,C2/C1)) -> 1 | K2: =IF(ROW()=2,0,ROUND(B2*G2,0)) -> 0 | L2: =IF(B2=0,0,K2/B2) -> 0 | M2: =IFERROR(COUNTIFS(tbl_Invoices[Month], A2),0) -> 9
A3: =IF(EDATE(A2,1) <= EOMONTH(MAX(tbl_Invoices[Invoice_Date]),0), EDATE(A2,1), "") -> 44255 | B3: {=_xlfn.LET( _xlpm.m, EOMONTH(A3,0), _xlpm.cust, _xlfn.UNIQUE(_xlfn._xlws.FILTER(tbl_Invoices[Customer_ID], tbl_Invoices[Month]=_xlpm.m)), ROWS(_xlpm.cust) )} -> 7 | C3: =IFERROR(SUMIFS(tbl_Invoices[Amount], tbl_Invoices[Month], A3, tbl_Invoices[Active_Flag], 1), 0) -> 159 | D3: =IFERROR(C3*12, 0) -> 1908 | E3: =IFERROR(C3/B3, 0) -> 22.714286 | F3: =IF(ROW()=2,0,IF(B2=0,0,MAX(B2-B3,0)/B2)) -> 0.22222222 | G3: =IF(ROW()=2,1,1-F3) -> 0.77777778 | H3: =IF(ROW()=2,0,MAX(C2-C3,0)) -> 92 | I3: =IF(ROW()=2,1,IF(C2=0,1,1-H3/C2)) -> 0.63346614 | J3: =IF(ROW()=2,1,IF(C2=0,1,C3/C2)) -> 0.63346614 | K3: =IF(ROW()=2,0,ROUND(B3*G3,0)) -> 5 | L3: =IF(B3=0,0,K3/B3) -> 0.71428571 | M3: =IFERROR(COUNTIFS(tbl_Invoices[Month], A3),0) -> 7
A4: =IF(EDATE(A3,1) <= EOMONTH(MAX(tbl_Invoices[Invoice_Date]),0), EDATE(A3,1), "") -> 44283 | B4: {=_xlfn.LET( _xlpm.m, EOMONTH(A4,0), _xlpm.cust, _xlfn.UNIQUE(_xlfn._xlws.FILTER(tbl_Invoices[Customer_ID], tbl_Invoices[Month]=_xlpm.m)), ROWS(_xlpm.cust) )} -> 9 | C4: =IFERROR(SUMIFS(tbl_Invoices[Amount], tbl_Invoices[Month], A4, tbl_Invoices[Active_Flag], 1), 0) -> 428 | D4: =IFERROR(C4*12, 0) -> 5136 | E4: =IFERROR(C4/B4, 0) -> 47.555556 | F4: =IF(ROW()=2,0,IF(B3=0,0,MAX(B3-B4,0)/B3)) -> 0 | G4: =IF(ROW()=2,1,1-F4) -> 1 | H4: =IF(ROW()=2,0,MAX(C3-C4,0)) -> 0 | I4: =IF(ROW()=2,1,IF(C3=0,1,1-H4/C3)) -> 1 | J4: =IF(ROW()=2,1,IF(C3=0,1,C4/C3)) -> 2.6918239 | K4: =IF(ROW()=2,0,ROUND(B4*G4,0)) -> 9 | L4: =IF(B4=0,0,K4/B4) -> 1 | M4: =IFERROR(COUNTIFS(tbl_Invoices[Month], A4),0) -> 12
A5: =IF(EDATE(A4,1) <= EOMONTH(MAX(tbl_Invoices[Invoice_Date]),0), EDATE(A4,1), "") -> 44314 | B5: {=_xlfn.LET( _xlpm.m, EOMONTH(A5,0), _xlpm.cust, _xlfn.UNIQUE(_xlfn._xlws.FILTER(tbl_Invoices[Customer_ID], tbl_Invoices[Month]=_xlpm.m)), ROWS(_xlpm.cust) )} -> 6 | C5: =IFERROR(SUMIFS(tbl_Invoices[Amount], tbl_Invoices[Month], A5, tbl_Invoices[Active_Flag], 1), 0) -> 239 | D5: =IFERROR(C5*12, 0) -> 2868 | E5: =IFERROR(C5/B5, 0) -> 39.833333 | F5: =IF(ROW()=2,0,IF(B4=0,0,MAX(B4-B5,0)/B4)) -> 0.33333333 | G5: =IF(ROW()=2,1,1-F5) -> 0.66666667 | H5: =IF(ROW()=2,0,MAX(C4-C5,0)) -> 189 | I5: =IF(ROW()=2,1,IF(C4=0,1,1-H5/C4)) -> 0.55841121 | J5: =IF(ROW()=2,1,IF(C4=0,1,C5/C4)) -> 0.55841121 | K5: =IF(ROW()=2,0,ROUND(B5*G5,0)) -> 4 | L5: =IF(B5=0,0,K5/B5) -> 0.66666667 | M5: =IFERROR(COUNTIFS(tbl_Invoices[Month], A5),0) -> 11
A6: =IF(EDATE(A5,1) <= EOMONTH(MAX(tbl_Invoices[Invoice_Date]),0), EDATE(A5,1), "") -> 44344 | B6: {=_xlfn.LET( _xlpm.m, EOMONTH(A6,0), _xlpm.cust, _xlfn.UNIQUE(_xlfn._xlws.FILTER(tbl_Invoices[Customer_ID], tbl_Invoices[Month]=_xlpm.m)), ROWS(_xlpm.cust) )} -> 11 | C6: =IFERROR(SUMIFS(tbl_Invoices[Amount], tbl_Invoices[Month], A6, tbl_Invoices[Active_Flag], 1), 0) -> 142 | D6: =IFERROR(C6*12, 0) -> 1704 | E6: =IFERROR(C6/B6, 0) -> 12.909091 | F6: =IF(ROW()=2,0,IF(B5=0,0,MAX(B5-B6,0)/B5)) -> 0 | G6: =IF(ROW()=2,1,1-F6) -> 1 | H6: =IF(ROW()=2,0,MAX(C5-C6,0)) -> 97 | I6: =IF(ROW()=2,1,IF(C5=0,1,1-H6/C5)) -> 0.59414226 | J6: =IF(ROW()=2,1,IF(C5=0,1,C6/C5)) -> 0.59414226 | K6: =IF(ROW()=2,0,ROUND(B6*G6,0)) -> 11 | L6: =IF(B6=0,0,K6/B6) -> 1 | M6: =IFERROR(COUNTIFS(tbl_Invoices[Month], A6),0) -> 6
A7: =IF(EDATE(A6,1) <= EOMONTH(MAX(tbl_Invoices[Invoice_Date]),0), EDATE(A6,1), "") -> 44375 | B7: {=_xlfn.LET( _xlpm.m, EOMONTH(A7,0), _xlpm.cust, _xlfn.UNIQUE(_xlfn._xlws.FILTER(tbl_Invoices[Customer_ID], tbl_Invoices[Month]=_xlpm.m)), ROWS(_xlpm.cust) )} -> 8 | C7: =IFERROR(SUMIFS(tbl_Invoices[Amount], tbl_Invoices[Month], A7, tbl_Invoices[Active_Flag], 1), 0) -> 49 | D7: =IFERROR(C7*12, 0) -> 588 | E7: =IFERROR(C7/B7, 0) -> 6.125 | F7: =IF(ROW()=2,0,IF(B6=0,0,MAX(B6-B7,0)/B6)) -> 0.27272727 | G7: =IF(ROW()=2,1,1-F7) -> 0.72727273 | H7: =IF(ROW()=2,0,MAX(C6-C7,0)) -> 93 | I7: =IF(ROW()=2,1,IF(C6=0,1,1-H7/C6)) -> 0.34507042 | J7: =IF(ROW()=2,1,IF(C6=0,1,C7/C6)) -> 0.34507042 | K7: =IF(ROW()=2,0,ROUND(B7*G7,0)) -> 6 | L7: =IF(B7=0,0,K7/B7) -> 0.75 | M7: =IFERROR(COUNTIFS(tbl_Invoices[Month], A7),0) -> 4
A8: =IF(EDATE(A7,1) <= EOMONTH(MAX(tbl_Invoices[Invoice_Date]),0), EDATE(A7,1), "") -> 44405 | B8: {=_xlfn.LET( _xlpm.m, EOMONTH(A8,0), _xlpm.cust, _xlfn.UNIQUE(_xlfn._xlws.FILTER(tbl_Invoices[Customer_ID], tbl_Invoices[Month]=_xlpm.m)), ROWS(_xlpm.cust) )} -> 6 | C8: =IFERROR(SUMIFS(tbl_Invoices[Amount], tbl_Invoices[Month], A8, tbl_Invoices[Active_Flag], 1), 0) -> 166 | D8: =IFERROR(C8*12, 0) -> 1992 | E8: =IFERROR(C8/B8, 0) -> 27.666667 | F8: =IF(ROW()=2,0,IF(B7=0,0,MAX(B7-B8,0)/B7)) -> 0.25 | G8: =IF(ROW()=2,1,1-F8) -> 0.75 | H8: =IF(ROW()=2,0,MAX(C7-C8,0)) -> 0 | I8: =IF(ROW()=2,1,IF(C7=0,1,1-H8/C7)) -> 1 | J8: =IF(ROW()=2,1,IF(C7=0,1,C8/C7)) -> 3.3877551 | K8: =IF(ROW()=2,0,ROUND(B8*G8,0)) -> 5 | L8: =IF(B8=0,0,K8/B8) -> 0.83333333 | M8: =IFERROR(COUNTIFS(tbl_Invoices[Month], A8),0) -> 8
A9: =IF(EDATE(A8,1) <= EOMONTH(MAX(tbl_Invoices[Invoice_Date]),0), EDATE(A8,1), "") -> 44436 | B9: {=_xlfn.LET( _xlpm.m, EOMONTH(A9,0), _xlpm.cust, _xlfn.UNIQUE(_xlfn._xlws.FILTER(tbl_Invoices[Customer_ID], tbl_Invoices[Month]=_xlpm.m)), ROWS(_xlpm.cust) )} -> 6 | C9: =IFERROR(SUMIFS(tbl_Invoices[Amount], tbl_Invoices[Month], A9, tbl_Invoices[Active_Flag], 1), 0) -> 117 | D9: =IFERROR(C9*12, 0) -> 1404 | E9: =IFERROR(C9/B9, 0) -> 19.5 | F9: =IF(ROW()=2,0,IF(B8=0,0,MAX(B8-B9,0)/B8)) -> 0 | G9: =IF(ROW()=2,1,1-F9) -> 1 | H9: =IF(ROW()=2,0,MAX(C8-C9,0)) -> 49 | I9: =IF(ROW()=2,1,IF(C8=0,1,1-H9/C8)) -> 0.70481928 | J9: =IF(ROW()=2,1,IF(C8=0,1,C9/C8)) -> 0.70481928 | K9: =IF(ROW()=2,0,ROUND(B9*G9,0)) -> 6 | L9: =IF(B9=0,0,K9/B9) -> 1 | M9: =IFERROR(COUNTIFS(tbl_Invoices[Month], A9),0) -> 6
A10: =IF(EDATE(A9,1) <= EOMONTH(MAX(tbl_Invoices[Invoice_Date]),0), EDATE(A9,1), "") -> 44467 | B10: {=_xlfn.LET( _xlpm.m, EOMONTH(A10,0), _xlpm.cust, _xlfn.UNIQUE(_xlfn._xlws.FILTER(tbl_Invoices[Customer_ID], tbl_Invoices[Month]=_xlpm.m)), ROWS(_xlpm.cust) )} -> 6 | C10: =IFERROR(SUMIFS(tbl_Invoices[Amount], tbl_Invoices[Month], A10, tbl_Invoices[Active_Flag], 1), 0) -> 172 | D10: =IFERROR(C10*12, 0) -> 2064 | E10: =IFERROR(C10/B10, 0) -> 28.666667 | F10: =IF(ROW()=2,0,IF(B9=0,0,MAX(B9-B10,0)/B9)) -> 0 | G10: =IF(ROW()=2,1,1-F10) -> 1 | H10: =IF(ROW()=2,0,MAX(C9-C10,0)) -> 0 | I10: =IF(ROW()=2,1,IF(C9=0,1,1-H10/C9)) -> 1 | J10: =IF(ROW()=2,1,IF(C9=0,1,C10/C9)) -> 1.4700855 | K10: =IF(ROW()=2,0,ROUND(B10*G10,0)) -> 6 | L10: =IF(B10=0,0,K10/B10) -> 1 | M10: =IFERROR(COUNTIFS(tbl_Invoices[Month], A10),0) -> 7
A11: =IF(EDATE(A10,1) <= EOMONTH(MAX(tbl_Invoices[Invoice_Date]),0), EDATE(A10,1), "") -> 44497 | B11: {=_xlfn.LET( _xlpm.m, EOMONTH(A11,0), _xlpm.cust, _xlfn.UNIQUE(_xlfn._xlws.FILTER(tbl_Invoices[Customer_ID], tbl_Invoices[Month]=_xlpm.m)), ROWS(_xlpm.cust) )} -> 5 | C11: =IFERROR(SUMIFS(tbl_Invoices[Amount], tbl_Invoices[Month], A11, tbl_Invoices[Active_Flag], 1), 0) -> 270 | D11: =IFERROR(C11*12, 0) -> 3240 | E11: =IFERROR(C11/B11, 0) -> 54 | F11: =IF(ROW()=2,0,IF(B10=0,0,MAX(B10-B11,0)/B10)) -> 0.16666667 | G11: =IF(ROW()=2,1,1-F11) -> 0.83333333 | H11: =IF(ROW()=2,0,MAX(C10-C11,0)) -> 0 | I11: =IF(ROW()=2,1,IF(C10=0,1,1-H11/C10)) -> 1 | J11: =IF(ROW()=2,1,IF(C10=0,1,C11/C10)) -> 1.5697674 | K11: =IF(ROW()=2,0,ROUND(B11*G11,0)) -> 4 | L11: =IF(B11=0,0,K11/B11) -> 0.8 | M11: =IFERROR(COUNTIFS(tbl_Invoices[Month], A11),0) -> 7
A12: =IF(EDATE(A11,1) <= EOMONTH(MAX(tbl_Invoices[Invoice_Date]),0), EDATE(A11,1), "") -> 44528 | B12: {=_xlfn.LET( _xlpm.m, EOMONTH(A12,0), _xlpm.cust, _xlfn.UNIQUE(_xlfn._xlws.FILTER(tbl_Invoices[Customer_ID], tbl_Invoices[Month]=_xlpm.m)), ROWS(_xlpm.cust) )} -> 6 | C12: =IFERROR(SUMIFS(tbl_Invoices[Amount], tbl_Invoices[Month], A12, tbl_Invoices[Active_Flag], 1), 0) -> 117 | D12: =IFERROR(C12*12, 0) -> 1404 | E12: =IFERROR(C12/B12, 0) -> 19.5 | F12: =IF(ROW()=2,0,IF(B11=0,0,MAX(B11-B12,0)/B11)) -> 0 | G12: =IF(ROW()=2,1,1-F12) -> 1 | H12: =IF(ROW()=2,0,MAX(C11-C12,0)) -> 153 | I12: =IF(ROW()=2,1,IF(C11=0,1,1-H12/C11)) -> 0.43333333 | J12: =IF(ROW()=2,1,IF(C11=0,1,C12/C11)) -> 0.43333333 | K12: =IF(ROW()=2,0,ROUND(B12*G12,0)) -> 6 | L12: =IF(B12=0,0,K12/B12) -> 1 | M12: =IFERROR(COUNTIFS(tbl_Invoices[Month], A12),0) -> 6
A13: =IF(EDATE(A12,1) <= EOMONTH(MAX(tbl_Invoices[Invoice_Date]),0), EDATE(A12,1), "") -> 44558 | B13: {=_xlfn.LET( _xlpm.m, EOMONTH(A13,0), _xlpm.cust, _xlfn.UNIQUE(_xlfn._xlws.FILTER(tbl_Invoices[Customer_ID], tbl_Invoices[Month]=_xlpm.m)), ROWS(_xlpm.cust) )} -> 5 | C13: =IFERROR(SUMIFS(tbl_Invoices[Amount], tbl_Invoices[Month], A13, tbl_Invoices[Active_Flag], 1), 0) -> 172 | D13: =IFERROR(C13*12, 0) -> 2064 | E13: =IFERROR(C13/B13, 0) -> 34.4 | F13: =IF(ROW()=2,0,IF(B12=0,0,MAX(B12-B13,0)/B12)) -> 0.16666667 | G13: =IF(ROW()=2,1,1-F13) -> 0.83333333 | H13: =IF(ROW()=2,0,MAX(C12-C13,0)) -> 0 | I13: =IF(ROW()=2,1,IF(C12=0,1,1-H13/C12)) -> 1 | J13: =IF(ROW()=2,1,IF(C12=0,1,C13/C12)) -> 1.4700855 | K13: =IF(ROW()=2,0,ROUND(B13*G13,0)) -> 4 | L13: =IF(B13=0,0,K13/B13) -> 0.8 | M13: =IFERROR(COUNTIFS(tbl_Invoices[Month], A13),0) -> 8
A14: =IF(EDATE(A13,1) <= EOMONTH(MAX(tbl_Invoices[Invoice_Date]),0), EDATE(A13,1), "") -> 44589 | B14: {=_xlfn.LET( _xlpm.m, EOMONTH(A14,0), _xlpm.cust, _xlfn.UNIQUE(_xlfn._xlws.FILTER(tbl_Invoices[Customer_ID], tbl_Invoices[Month]=_xlpm.m)), ROWS(_xlpm.cust) )} -> 3 | C14: =IFERROR(SUMIFS(tbl_Invoices[Amount], tbl_Invoices[Month], A14, tbl_Invoices[Active_Flag], 1), 0) -> 135 | D14: =IFERROR(C14*12, 0) -> 1620 | E14: =IFERROR(C14/B14, 0) -> 45 | F14: =IF(ROW()=2,0,IF(B13=0,0,MAX(B13-B14,0)/B13)) -> 0.4 | G14: =IF(ROW()=2,1,1-F14) -> 0.6 | H14: =IF(ROW()=2,0,MAX(C13-C14,0)) -> 37 | I14: =IF(ROW()=2,1,IF(C13=0,1,1-H14/C13)) -> 0.78488372 | J14: =IF(ROW()=2,1,IF(C13=0,1,C14/C13)) -> 0.78488372 | K14: =IF(ROW()=2,0,ROUND(B14*G14,0)) -> 2 | L14: =IF(B14=0,0,K14/B14) -> 0.66666667 | M14: =IFERROR(COUNTIFS(tbl_Invoices[Month], A14),0) -> 5
... A30: =IF(EDATE(A29,1) <= EOMONTH(MAX(tbl_Invoices[Invoice_Date]),0), EDATE(A29,1), "") -> 45074 | B30: {=_xlfn.LET( _xlpm.m, EOMONTH(A30,0), _xlpm.cust, _xlfn.UNIQUE(_xlfn._xlws.FILTER(tbl_Invoices[Customer_ID], tbl_Invoices[Month]=_xlpm.m)), ROWS(_xlpm.cust) )} -> 5 | C30: =IFERROR(SUMIFS(tbl_Invoices[Amount], tbl_Invoices[Month], A30, tbl_Invoices[Active_Flag], 1), 0) -> 257 | D30: =IFERROR(C30*12, 0) -> 3084 | E30: =IFERROR(C30/B30, 0) -> 51.4 | F30: =IF(ROW()=2,0,IF(B29=0,0,MAX(B29-B30,0)/B29)) -> 0.44444444 | G30: =IF(ROW()=2,1,1-F30) -> 0.55555556 | H30: =IF(ROW()=2,0,MAX(C29-C30,0)) -> 7 | I30: =IF(ROW()=2,1,IF(C29=0,1,1-H30/C29)) -> 0.97348485 | J30: =IF(ROW()=2,1,IF(C29=0,1,C30/C29)) -> 0.97348485 | K30: =IF(ROW()=2,0,ROUND(B30*G30,0)) -> 3 | L30: =IF(B30=0,0,K30/B30) -> 0.6 | M30: =IFERROR(COUNTIFS(tbl_Invoices[Month], A30),0) -> 7

Sheet Customers
A1: Customer_ID | B1: Signup_Date | C1: Birth_Year | D1: Region | E1: Acquisition_Channel | F1: Plan_At_Signup | G1: Age | H1: Age_Group | I1: Cohort_Month
A2: C0001 | B2: 44851 | C2: 2003 | D2: East | E2: Paid Ads | F2: Premium | G2: =YEAR(TODAY()) - tbl_Customers[[#This Row],[Birth_Year]] -> 22 | H2: {=_xlfn.IFS( tbl_Customers[[#This Row],[Age]] < 25, "18–24", tbl_Customers[[#This Row],[Age]] < 35, "25–34", tbl_Customers[[#This Row],[Age]] < 45, "35–44", tbl_Customers[[#This Row],[Age]] < 55, "45–54", TRUE, "55+" )} -> 18–24 | I2: =EOMONTH(tbl_Customers[[#This Row],[Signup_Date]], 0) -> 44865
A3: C0002 | B3: 44311 | C3: 1993 | D3: East | E3: Paid Ads | F3: Premium | G3: =YEAR(TODAY()) - tbl_Customers[[#This Row],[Birth_Year]] -> 32 | H3: {=_xlfn.IFS( tbl_Customers[[#This Row],[Age]] < 25, "18–24", tbl_Customers[[#This Row],[Age]] < 35, "25–34", tbl_Customers[[#This Row],[Age]] < 45, "35–44", tbl_Customers[[#This Row],[Age]] < 55, "45–54", TRUE, "55+" )} -> 25–34 | I3: =EOMONTH(tbl_Customers[[#This Row],[Signup_Date]], 0) -> 44316
A4: C0003 | B4: 44222 | C4: 1979 | D4: Midwest | E4: Affiliate | F4: Basic | G4: =YEAR(TODAY()) - tbl_Customers[[#This Row],[Birth_Year]] -> 46 | H4: {=_xlfn.IFS( tbl_Customers[[#This Row],[Age]] < 25, "18–24", tbl_Customers[[#This Row],[Age]] < 35, "25–34", tbl_Customers[[#This Row],[Age]] < 45, "35–44", tbl_Customers[[#This Row],[Age]] < 55, "45–54", TRUE, "55+" )} -> 45–54 | I4: =EOMONTH(tbl_Customers[[#This Row],[Signup_Date]], 0) -> 44227
A5: C0004 | B5: 44956 | C5: 1972 | D5: East | E5: Affiliate | F5: Premium | G5: =YEAR(TODAY()) - tbl_Customers[[#This Row],[Birth_Year]] -> 53 | H5: {=_xlfn.IFS( tbl_Customers[[#This Row],[Age]] < 25, "18–24", tbl_Customers[[#This Row],[Age]] < 35, "25–34", tbl_Customers[[#This Row],[Age]] < 45, "35–44", tbl_Customers[[#This Row],[Age]] < 55, "45–54", TRUE, "55+" )} -> 45–54 | I5: =EOMONTH(tbl_Customers[[#This Row],[Signup_Date]], 0) -> 44957
A6: C0005 | B6: 44478 | C6: 1985 | D6: South | E6: Affiliate | F6: Premium | G6: =YEAR(TODAY()) - tbl_Customers[[#This Row],[Birth_Year]] -> 40 | H6: {=_xlfn.IFS( tbl_Customers[[#This Row],[Age]] < 25, "18–24", tbl_Customers[[#This Row],[Age]] < 35, "25–34", tbl_Customers[[#This Row],[Age]] < 45, "35–44", tbl_Customers[[#This Row],[Age]] < 55, "45–54", TRUE, "55+" )} -> 35–44 | I6: =EOMONTH(tbl_Customers[[#This Row],[Signup_Date]], 0) -> 44500
A7: C0006 | B7: 44447 | C7: 2003 | D7: International | E7: Paid Ads | F7: Standard | G7: =YEAR(TODAY()) - tbl_Customers[[#This Row],[Birth_Year]] -> 22 | H7: {=_xlfn.IFS( tbl_Customers[[#This Row],[Age]] < 25, "18–24", tbl_Customers[[#This Row],[Age]] < 35, "25–34", tbl_Customers[[#This Row],[Age]] < 45, "35–44", tbl_Customers[[#This Row],[Age]] < 55, "45–54", TRUE, "55+" )} -> 18–24 | I7: =EOMONTH(tbl_Customers[[#This Row],[Signup_Date]], 0) -> 44469
A8: C0007 | B8: 44425 | C8: 1983 | D8: East | E8: Referral | F8: Standard | G8: =YEAR(TODAY()) - tbl_Customers[[#This Row],[Birth_Year]] -> 42 | H8: {=_xlfn.IFS( tbl_Customers[[#This Row],[Age]] < 25, "18–24", tbl_Customers[[#This Row],[Age]] < 35, "25–34", tbl_Customers[[#This Row],[Age]] < 45, "35–44", tbl_Customers[[#This Row],[Age]] < 55, "45–54", TRUE, "55+" )} -> 35–44 | I8: =EOMONTH(tbl_Customers[[#This Row],[Signup_Date]], 0) -> 44439
A9: C0008 | B9: 44339 | C9: 1987 | D9: South | E9: Social Media | F9: Basic | G9: =YEAR(TODAY()) - tbl_Customers[[#This Row],[Birth_Year]] -> 38 | H9: {=_xlfn.IFS( tbl_Customers[[#This Row],[Age]] < 25, "18–24", tbl_Customers[[#This Row],[Age]] < 35, "25–34", tbl_Customers[[#This Row],[Age]] < 45, "35–44", tbl_Customers[[#This Row],[Age]] < 55, "45–54", TRUE, "55+" )} -> 35–44 | I9: =EOMONTH(tbl_Customers[[#This Row],[Signup_Date]], 0) -> 44347
A10: C0009 | B10: 44951 | C10: 1975 | D10: West | E10: Affiliate | F10: Standard | G10: =YEAR(TODAY()) - tbl_Customers[[#This Row],[Birth_Year]] -> 50 | H10: {=_xlfn.IFS( tbl_Customers[[#This Row],[Age]] < 25, "18–24", tbl_Customers[[#This Row],[Age]] < 35, "25–34", tbl_Customers[[#This Row],[Age]] < 45, "35–44", tbl_Customers[[#This Row],[Age]] < 55, "45–54", TRUE, "55+" )} -> 45–54 | I10: =EOMONTH(tbl_Customers[[#This Row],[Signup_Date]], 0) -> 44957
A11: C0010 | B11: 44301 | C11: 1975 | D11: South | E11: Referral | F11: Standard | G11: =YEAR(TODAY()) - tbl_Customers[[#This Row],[Birth_Year]] -> 50 | H11: {=_xlfn.IFS( tbl_Customers[[#This Row],[Age]] < 25, "18–24", tbl_Customers[[#This Row],[Age]] < 35, "25–34", tbl_Customers[[#This Row],[Age]] < 45, "35–44", tbl_Customers[[#This Row],[Age]] < 55, "45–54", TRUE, "55+" )} -> 45–54 | I11: =EOMONTH(tbl_Customers[[#This Row],[Signup_Date]], 0) -> 44316
A12: C0011 | B12: 44889 | C12: 1988 | D12: International | E12: Organic Search | F12: Premium | G12: =YEAR(TODAY()) - tbl_Customers[[#This Row],[Birth_Year]] -> 37 | H12: {=_xlfn.IFS( tbl_Customers[[#This Row],[Age]] < 25, "18–24", tbl_Customers[[#This Row],[Age]] < 35, "25–34", tbl_Customers[[#This Row],[Age]] < 45, "35–44", tbl_Customers[[#This Row],[Age]] < 55, "45–54", TRUE, "55+" )} -> 35–44 | I12: =EOMONTH(tbl_Customers[[#This Row],[Signup_Date]], 0) -> 44895
A13: C0012 | B13: 44955 | C13: 2000 | D13: South | E13: Affiliate | F13: Premium | G13: =YEAR(TODAY()) - tbl_Customers[[#This Row],[Birth_Year]] -> 25 | H13: {=_xlfn.IFS( tbl_Customers[[#This Row],[Age]] < 25, "18–24", tbl_Customers[[#This Row],[Age]] < 35, "25–34", tbl_Customers[[#This Row],[Age]] < 45, "35–44", tbl_Customers[[#This Row],[Age]] < 55, "45–54", TRUE, "55+" )} -> 25–34 | I13: =EOMONTH(tbl_Customers[[#This Row],[Signup_Date]], 0) -> 44957
... A2001: C2000 | B2001: 44382 | C2001: 1967 | D2001: West | E2001: Organic Search | F2001: Standard | G2001: =YEAR(TODAY()) - tbl_Customers[[#This Row],[Birth_Year]] -> 58 | H2001: {=_xlfn.IFS( tbl_Customers[[#This Row],[Age]] < 25, "18–24", tbl_Customers[[#This Row],[Age]] < 35, "25–34", tbl_Customers[[#This Row],[Age]] < 45, "35–44", tbl_Customers[[#This Row],[Age]] < 55, "45–54", TRUE, "55+" )} -> 55+ | I2001: =EOMONTH(tbl_Customers[[#This Row],[Signup_Date]], 0) -> 44408

Sheet Subscriptions
A1: Subscription_ID | B1: Customer_ID | C1: Plan_ID | D1: Start_Date | E1: End_Date | F1: Cancel_Date | G1: Cancel_Reason | H1: Is_Trial | I1: Start Month | J1: Cancel_Month
A2: S00001 | B2: C1388 | C2: P1 | D2: 45087 | E2: 45336 | F2: 45336 | G2: No Value | H2: FALSE | I2: =EOMONTH(tbl_Subscriptions[[#This Row],[Start_Date]],0) -> 45107 | J2: =IF(tbl_Subscriptions[[#This Row],[Cancel_Date]]="","",EOMONTH(tbl_Subscriptions[[#This Row],[Cancel_Date]],0)) -> 45351
A3: S00002 | B3: C1154 | C3: P1 | D3: 44343 | H3: FALSE | I3: =EOMONTH(tbl_Subscriptions[[#This Row],[Start_Date]],0) -> 44347 | J3: =IF(tbl_Subscriptions[[#This Row],[Cancel_Date]]="","",EOMONTH(tbl_Subscriptions[[#This Row],[Cancel_Date]],0))
A4: S00003 | B4: C0084 | C4: P3 | D4: 44776 | H4: FALSE | I4: =EOMONTH(tbl_Subscriptions[[#This Row],[Start_Date]],0) -> 44804 | J4: =IF(tbl_Subscriptions[[#This Row],[Cancel_Date]]="","",EOMONTH(tbl_Subscriptions[[#This Row],[Cancel_Date]],0))
A5: S00004 | B5: C0271 | C5: P1 | D5: 44870 | H5: TRUE | I5: =EOMONTH(tbl_Subscriptions[[#This Row],[Start_Date]],0) -> 44895 | J5: =IF(tbl_Subscriptions[[#This Row],[Cancel_Date]]="","",EOMONTH(tbl_Subscriptions[[#This Row],[Cancel_Date]],0))
A6: S00005 | B6: C0244 | C6: P2 | D6: 44607 | E6: 44777 | F6: 44777 | G6: No Value | H6: FALSE | I6: =EOMONTH(tbl_Subscriptions[[#This Row],[Start_Date]],0) -> 44620 | J6: =IF(tbl_Subscriptions[[#This Row],[Cancel_Date]]="","",EOMONTH(tbl_Subscriptions[[#This Row],[Cancel_Date]],0)) -> 44804
A7: S00006 | B7: C0388 | C7: P3 | D7: 44268 | H7: TRUE | I7: =EOMONTH(tbl_Subscriptions[[#This Row],[Start_Date]],0) -> 44286 | J7: =IF(tbl_Subscriptions[[#This Row],[Cancel_Date]]="","",EOMONTH(tbl_Subscriptions[[#This Row],[Cancel_Date]],0))
A8: S00007 | B8: C0214 | C8: P3 | D8: 44342 | E8: 44562 | F8: 44562 | G8: Switched | H8: TRUE | I8: =EOMONTH(tbl_Subscriptions[[#This Row],[Start_Date]],0) -> 44347 | J8: =IF(tbl_Subscriptions[[#This Row],[Cancel_Date]]="","",EOMONTH(tbl_Subscriptions[[#This Row],[Cancel_Date]],0)) -> 44592
A9: S00008 | B9: C0818 | C9: P1 | D9: 44955 | H9: FALSE | I9: =EOMONTH(tbl_Subscriptions[[#This Row],[Start_Date]],0) -> 44957 | J9: =IF(tbl_Subscriptions[[#This Row],[Cancel_Date]]="","",EOMONTH(tbl_Subscriptions[[#This Row],[Cancel_Date]],0))
A10: S00009 | B10: C1190 | C10: P1 | D10: 44845 | E10: 45077 | F10: 45077 | G10: Switched | H10: FALSE | I10: =EOMONTH(tbl_Subscriptions[[#This Row],[Start_Date]],0) -> 44865 | J10: =IF(tbl_Subscriptions[[#This Row],[Cancel_Date]]="","",EOMONTH(tbl_Subscriptions[[#This Row],[Cancel_Date]],0)) -> 45077
A11: S00010 | B11: C1815 | C11: P2 | D11: 44228 | E11: 44377 | F11: 44377 | G11: Too Expensive | H11: TRUE | I11: =EOMONTH(tbl_Subscriptions[[#This Row],[Start_Date]],0) -> 44255 | J11: =IF(tbl_Subscriptions[[#This Row],[Cancel_Date]]="","",EOMONTH(tbl_Subscriptions[[#This Row],[Cancel_Date]],0)) -> 44377
A12: S00011 | B12: C0059 | C12: P3 | D12: 44290 | H12: FALSE | I12: =EOMONTH(tbl_Subscriptions[[#This Row],[Start_Date]],0) -> 44316 | J12: =IF(tbl_Subscriptions[[#This Row],[Cancel_Date]]="","",EOMONTH(tbl_Subscriptions[[#This Row],[Cancel_Date]],0))
A13: S00012 | B13: C1626 | C13: P1 | D13: 44961 | H13: FALSE | I13: =EOMONTH(tbl_Subscriptions[[#This Row],[Start_Date]],0) -> 44985 | J13: =IF(tbl_Subscriptions[[#This Row],[Cancel_Date]]="","",EOMONTH(tbl_Subscriptions[[#This Row],[Cancel_Date]],0))
A14: S00013 | B14: C0883 | C14: P2 | D14: 44740 | E14: 45014 | F14: 45014 | G14: No Value | H14: FALSE | I14: =EOMONTH(tbl_Subscriptions[[#This Row],[Start_Date]],0) -> 44742 | J14: =IF(tbl_Subscriptions[[#This Row],[Cancel_Date]]="","",EOMONTH(tbl_Subscriptions[[#This Row],[Cancel_Date]],0)) -> 45016
A15: S00014 | B15: C0843 | C15: P1 | D15: 44417 | E15: 44562 | F15: 44562 | G15: Switched | H15: FALSE | I15: =EOMONTH(tbl_Subscriptions[[#This Row],[Start_Date]],0) -> 44439 | J15: =IF(tbl_Subscriptions[[#This Row],[Cancel_Date]]="","",EOMONTH(tbl_Subscriptions[[#This Row],[Cancel_Date]],0)) -> 44592
A16: S00015 | B16: C0924 | C16: P3 | D16: 44582 | H16: FALSE | I16: =EOMONTH(tbl_Subscriptions[[#This Row],[Start_Date]],0) -> 44592 | J16: =IF(tbl_Subscriptions[[#This Row],[Cancel_Date]]="","",EOMONTH(tbl_Subscriptions[[#This Row],[Cancel_Date]],0))
A17: S00016 | B17: C1528 | C17: P1 | D17: 44626 | E17: 44831 | F17: 44831 | G17: No Value | H17: FALSE | I17: =EOMONTH(tbl_Subscriptions[[#This Row],[Start_Date]],0) -> 44651 | J17: =IF(tbl_Subscriptions[[#This Row],[Cancel_Date]]="","",EOMONTH(tbl_Subscriptions[[#This Row],[Cancel_Date]],0)) -> 44834
A18: S00017 | B18: C1730 | C18: P3 | D18: 44661 | H18: FALSE | I18: =EOMONTH(tbl_Subscriptions[[#This Row],[Start_Date]],0) -> 44681 | J18: =IF(tbl_Subscriptions[[#This Row],[Cancel_Date]]="","",EOMONTH(tbl_Subscriptions[[#This Row],[Cancel_Date]],0))
A19: S00018 | B19: C0123 | C19: P1 | D19: 44546 | H19: TRUE | I19: =EOMONTH(tbl_Subscriptions[[#This Row],[Start_Date]],0) -> 44561 | J19: =IF(tbl_Subscriptions[[#This Row],[Cancel_Date]]="","",EOMONTH(tbl_Subscriptions[[#This Row],[Cancel_Date]],0))
A20: S00019 | B20: C1672 | C20: P3 | D20: 44358 | E20: 44424 | F20: 44424 | G20: No Value | H20: FALSE | I20: =EOMONTH(tbl_Subscriptions[[#This Row],[Start_Date]],0) -> 44377 | J20: =IF(tbl_Subscriptions[[#This Row],[Cancel_Date]]="","",EOMONTH(tbl_Subscriptions[[#This Row],[Cancel_Date]],0)) -> 44439
A21: S00020 | B21: C1437 | C21: P2 | D21: 44575 | H21: FALSE | I21: =EOMONTH(tbl_Subscriptions[[#This Row],[Start_Date]],0) -> 44592 | J21: =IF(tbl_Subscriptions[[#This Row],[Cancel_Date]]="","",EOMONTH(tbl_Subscriptions[[#This Row],[Cancel_Date]],0))
A22: S00021 | B22: C1163 | C22: P3 | D22: 44516 | H22: FALSE | I22: =EOMONTH(tbl_Subscriptions[[#This Row],[Start_Date]],0) -> 44530 | J22: =IF(tbl_Subscriptions[[#This Row],[Cancel_Date]]="","",EOMONTH(tbl_Subscriptions[[#This Row],[Cancel_Date]],0))
A23: S00022 | B23: C1253 | C23: P2 | D23: 44935 | E23: 45125 | F23: 45125 | G23: Too Expensive | H23: FALSE | I23: =EOMONTH(tbl_Subscriptions[[#This Row],[Start_Date]],0) -> 44957 | J23: =IF(tbl_Subscriptions[[#This Row],[Cancel_Date]]="","",EOMONTH(tbl_Subscriptions[[#This Row],[Cancel_Date]],0)) -> 45138
A24: S00023 | B24: C1298 | C24: P3 | D24: 44529 | H24: FALSE | I24: =EOMONTH(tbl_Subscriptions[[#This Row],[Start_Date]],0) -> 44530 | J24: =IF(tbl_Subscriptions[[#This Row],[Cancel_Date]]="","",EOMONTH(tbl_Subscriptions[[#This Row],[Cancel_Date]],0))
A25: S00024 | B25: C0439 | C25: P2 | D25: 44992 | E25: 45090 | F25: 45090 | G25: Switched | H25: FALSE | I25: =EOMONTH(tbl_Subscriptions[[#This Row],[Start_Date]],0) -> 45016 | J25: =IF(tbl_Subscriptions[[#This Row],[Cancel_Date]]="","",EOMONTH(tbl_Subscriptions[[#This Row],[Cancel_Date]],0)) -> 45107
A26: S00025 | B26: C1022 | C26: P1 | D26: 44778 | H26: FALSE | I26: =EOMONTH(tbl_Subscriptions[[#This Row],[Start_Date]],0) -> 44804 | J26: =IF(tbl_Subscriptions[[#This Row],[Cancel_Date]]="","",EOMONTH(tbl_Subscriptions[[#This Row],[Cancel_Date]],0))
A27: S00026 | B27: C0562 | C27: P3 | D27: 44807 | E27: 44841 | F27: 44841 | G27: Switched | H27: FALSE | I27: =EOMONTH(tbl_Subscriptions[[#This Row],[Start_Date]],0) -> 44834 | J27: =IF(tbl_Subscriptions[[#This Row],[Cancel_Date]]="","",EOMONTH(tbl_Subscriptions[[#This Row],[Cancel_Date]],0)) -> 44865
A28: S00027 | B28: C1934 | C28: P1 | D28: 44283 | H28: FALSE | I28: =EOMONTH(tbl_Subscriptions[[#This Row],[Start_Date]],0) -> 44286 | J28: =IF(tbl_Subscriptions[[#This Row],[Cancel_Date]]="","",EOMONTH(tbl_Subscriptions[[#This Row],[Cancel_Date]],0))
A29: S00028 | B29: C0118 | C29: P2 | D29: 44250 | H29: FALSE | I29: =EOMONTH(tbl_Subscriptions[[#This Row],[Start_Date]],0) -> 44255 | J29: =IF(tbl_Subscriptions[[#This Row],[Cancel_Date]]="","",EOMONTH(tbl_Subscriptions[[#This Row],[Cancel_Date]],0))
A30: S00029 | B30: C1738 | C30: P3 | D30: 44356 | H30: TRUE | I30: =EOMONTH(tbl_Subscriptions[[#This Row],[Start_Date]],0) -> 44377 | J30: =IF(tbl_Subscriptions[[#This Row],[Cancel_Date]]="","",EOMONTH(tbl_Subscriptions[[#This Row],[Cancel_Date]],0))
A31: S00030 | B31: C0905 | C31: P3 | D31: 44358 | H31: FALSE | I31: =EOMONTH(tbl_Subscriptions[[#This Row],[Start_Date]],0) -> 44377 | J31: =IF(tbl_Subscriptions[[#This Row],[Cancel_Date]]="","",EOMONTH(tbl_Subscriptions[[#This Row],[Cancel_Date]],0))
A32: S00031 | B32: C1507 | C32: P1 | D32: 44969 | E32: 45209 | F32: 45209 | G32: Switched | H32: FALSE | I32: =EOMONTH(tbl_Subscriptions[[#This Row],[Start_Date]],0) -> 44985 | J32: =IF(tbl_Subscriptions[[#This Row],[Cancel_Date]]="","",EOMONTH(tbl_Subscriptions[[#This Row],[Cancel_Date]],0)) -> 45230
A33: S00032 | B33: C0395 | C33: P3 | D33: 44829 | H33: FALSE | I33: =EOMONTH(tbl_Subscriptions[[#This Row],[Start_Date]],0) -> 44834 | J33: =IF(tbl_Subscriptions[[#This Row],[Cancel_Date]]="","",EOMONTH(tbl_Subscriptions[[#This Row],[Cancel_Date]],0))
A34: S00033 | B34: C1727 | C34: P3 | D34: 44247 | H34: FALSE | I34: =EOMONTH(tbl_Subscriptions[[#This Row],[Start_Date]],0) -> 44255 | J34: =IF(tbl_Subscriptions[[#This Row],[Cancel_Date]]="","",EOMONTH(tbl_Subscriptions[[#This Row],[Cancel_Date]],0))
A35: S00034 | B35: C0876 | C35: P1 | D35: 44887 | E35: 44968 | F35: 44968 | G35: No Value | H35: FALSE | I35: =EOMONTH(tbl_Subscriptions[[#This Row],[Start_Date]],0) -> 44895 | J35: =IF(tbl_Subscriptions[[#This Row],[Cancel_Date]]="","",EOMONTH(tbl_Subscriptions[[#This Row],[Cancel_Date]],0)) -> 44985
A36: S00035 | B36: C1484 | C36: P3 | D36: 44280 | H36: FALSE | I36: =EOMONTH(tbl_Subscriptions[[#This Row],[Start_Date]],0) -> 44286 | J36: =IF(tbl_Subscriptions[[#This Row],[Cancel_Date]]="","",EOMONTH(tbl_Subscriptions[[#This Row],[Cancel_Date]],0))
A37: S00036 | B37: C1859 | C37: P1 | D37: 44475 | H37: FALSE | I37: =EOMONTH(tbl_Subscriptions[[#This Row],[Start_Date]],0) -> 44500 | J37: =IF(tbl_Subscriptions[[#This Row],[Cancel_Date]]="","",EOMONTH(tbl_Subscriptions[[#This Row],[Cancel_Date]],0))
A38: S00037 | B38: C1717 | C38: P1 | D38: 44650 | H38: FALSE | I38: =EOMONTH(tbl_Subscriptions[[#This Row],[Start_Date]],0) -> 44651 | J38: =IF(tbl_Subscriptions[[#This Row],[Cancel_Date]]="","",EOMONTH(tbl_Subscriptions[[#This Row],[Cancel_Date]],0))
A39: S00038 | B39: C0935 | C39: P1 | D39: 44874 | H39: FALSE | I39: =EOMONTH(tbl_Subscriptions[[#This Row],[Start_Date]],0) -> 44895 | J39: =IF(tbl_Subscriptions[[#This Row],[Cancel_Date]]="","",EOMONTH(tbl_Subscriptions[[#This Row],[Cancel_Date]],0))
A40: S00039 | B40: C1102 | C40: P1 | D40: 44631 | E40: 44732 | F40: 44732 | G40: No Value | H40: FALSE | I40: =EOMONTH(tbl_Subscriptions[[#This Row],[Start_Date]],0) -> 44651 | J40: =IF(tbl_Subscriptions[[#This Row],[Cancel_Date]]="","",EOMONTH(tbl_Subscriptions[[#This Row],[Cancel_Date]],0)) -> 44742
...

Sheet Invoices
A1: Invoice_ID | B1: Customer_ID | C1: Subscription_ID | D1: Invoice_Date | E1: Amount | F1: Is_Recurring | G1: Revenue_Type | H1: Plan_ID | I1: Month | J1: Year | K1: Cohort_Month | L1: Age_Group | M1: Region | N1: Plan_Name | O1: Active_Flag
A2: I001251 | B2: C0228 | C2: S00657 | D2: 44197 | E2: 55 | F2: TRUE | G2: New | H2: P3 | I2: =DATE(YEAR(tbl_Invoices[[#This Row],[Invoice_Date]]), MONTH(tbl_Invoices[[#This Row],[Invoice_Date]]), DAY(tbl_Invoices[[#This Row],[Invoice_Date]])) -> 44197 | J2: =YEAR(tbl_Invoices[[#This Row],[Invoice_Date]]) -> 2021 | K2: =_xlfn.XLOOKUP(tbl_Invoices[[#This Row],[Customer_ID]], tbl_Customers[Customer_ID], tbl_Customers[Cohort_Month]) -> 44316 | L2: =_xlfn.XLOOKUP(tbl_Invoices[[#This Row],[Customer_ID]], tbl_Customers[Customer_ID], tbl_Customers[Age_Group]) -> 45–54 | M2: =_xlfn.XLOOKUP(tbl_Invoices[[#This Row],[Customer_ID]], tbl_Customers[Customer_ID], tbl_Customers[Region]) -> International | N2: {=_xlfn.IFS( _xlfn.SINGLE(tbl_Invoices[Plan_ID])="P1","Basic", _xlfn.SINGLE(tbl_Invoices[Plan_ID])="P2","Standard", _xlfn.SINGLE(tbl_Invoices[Plan_ID])="P3","Premium" )} -> Premium | O2: =IF(tbl_Invoices[[#This Row],[Revenue_Type]]="Churned",0,1) -> 1
A3: I005864 | B3: C0385 | C3: S02209 | D3: 44197 | E3: 55 | F3: TRUE | G3: Expansion | H3: P3 | I3: =DATE(YEAR(tbl_Invoices[[#This Row],[Invoice_Date]]), MONTH(tbl_Invoices[[#This Row],[Invoice_Date]]), DAY(tbl_Invoices[[#This Row],[Invoice_Date]])) -> 44197 | J3: =YEAR(tbl_Invoices[[#This Row],[Invoice_Date]]) -> 2021 | K3: =_xlfn.XLOOKUP(tbl_Invoices[[#This Row],[Customer_ID]], tbl_Customers[Customer_ID], tbl_Customers[Cohort_Month]) -> 44773 | L3: =_xlfn.XLOOKUP(tbl_Invoices[[#This Row],[Customer_ID]], tbl_Customers[Customer_ID], tbl_Customers[Age_Group]) -> 45–54 | M3: =_xlfn.XLOOKUP(tbl_Invoices[[#This Row],[Customer_ID]], tbl_Customers[Customer_ID], tbl_Customers[Region]) -> Midwest | N3: {=_xlfn.IFS( _xlfn.SINGLE(tbl_Invoices[Plan_ID])="P1","Basic", _xlfn.SINGLE(tbl_Invoices[Plan_ID])="P2","Standard", _xlfn.SINGLE(tbl_Invoices[Plan_ID])="P3","Premium" )} -> Premium | O3: =IF(tbl_Invoices[[#This Row],[Revenue_Type]]="Churned",0,1) -> 1
A4: I005689 | B4: C0606 | C4: S01026 | D4: 44197 | E4: 55 | F4: TRUE | G4: Contraction | H4: P3 | I4: =DATE(YEAR(tbl_Invoices[[#This Row],[Invoice_Date]]), MONTH(tbl_Invoices[[#This Row],[Invoice_Date]]), DAY(tbl_Invoices[[#This Row],[Invoice_Date]])) -> 44197 | J4: =YEAR(tbl_Invoices[[#This Row],[Invoice_Date]]) -> 2021 | K4: =_xlfn.XLOOKUP(tbl_Invoices[[#This Row],[Customer_ID]], tbl_Customers[Customer_ID], tbl_Customers[Cohort_Month]) -> 44500 | L4: =_xlfn.XLOOKUP(tbl_Invoices[[#This Row],[Customer_ID]], tbl_Customers[Customer_ID], tbl_Customers[Age_Group]) -> 25–34 | M4: =_xlfn.XLOOKUP(tbl_Invoices[[#This Row],[Customer_ID]], tbl_Customers[Customer_ID], tbl_Customers[Region]) -> East | N4: {=_xlfn.IFS( _xlfn.SINGLE(tbl_Invoices[Plan_ID])="P1","Basic", _xlfn.SINGLE(tbl_Invoices[Plan_ID])="P2","Standard", _xlfn.SINGLE(tbl_Invoices[Plan_ID])="P3","Premium" )} -> Premium | O4: =IF(tbl_Invoices[[#This Row],[Revenue_Type]]="Churned",0,1) -> 1
A5: I003239 | B5: C1750 | C5: S02213 | D5: 44197 | E5: 55 | F5: TRUE | G5: Expansion | H5: P3 | I5: =DATE(YEAR(tbl_Invoices[[#This Row],[Invoice_Date]]), MONTH(tbl_Invoices[[#This Row],[Invoice_Date]]), DAY(tbl_Invoices[[#This Row],[Invoice_Date]])) -> 44197 | J5: =YEAR(tbl_Invoices[[#This Row],[Invoice_Date]]) -> 2021 | K5: =_xlfn.XLOOKUP(tbl_Invoices[[#This Row],[Customer_ID]], tbl_Customers[Customer_ID], tbl_Customers[Cohort_Month]) -> 44500 | L5: =_xlfn.XLOOKUP(tbl_Invoices[[#This Row],[Customer_ID]], tbl_Customers[Customer_ID], tbl_Customers[Age_Group]) -> 25–34 | M5: =_xlfn.XLOOKUP(tbl_Invoices[[#This Row],[Customer_ID]], tbl_Customers[Customer_ID], tbl_Customers[Region]) -> East | N5: {=_xlfn.IFS( _xlfn.SINGLE(tbl_Invoices[Plan_ID])="P1","Basic", _xlfn.SINGLE(tbl_Invoices[Plan_ID])="P2","Standard", _xlfn.SINGLE(tbl_Invoices[Plan_ID])="P3","Premium" )} -> Premium | O5: =IF(tbl_Invoices[[#This Row],[Revenue_Type]]="Churned",0,1) -> 1
A6: I003747 | B6: C1957 | C6: S01715 | D6: 44197 | E6: 25 | F6: TRUE | G6: Contraction | H6: P2 | I6: =DATE(YEAR(tbl_Invoices[[#This Row],[Invoice_Date]]), MONTH(tbl_Invoices[[#This Row],[Invoice_Date]]), DAY(tbl_Invoices[[#This Row],[Invoice_Date]])) -> 44197 | J6: =YEAR(tbl_Invoices[[#This Row],[Invoice_Date]]) -> 2021 | K6: =_xlfn.XLOOKUP(tbl_Invoices[[#This Row],[Customer_ID]], tbl_Customers[Customer_ID], tbl_Customers[Cohort_Month]) -> 44742 | L6: =_xlfn.XLOOKUP(tbl_Invoices[[#This Row],[Customer_ID]], tbl_Customers[Customer_ID], tbl_Customers[Age_Group]) -> 25–34 | M6: =_xlfn.XLOOKUP(tbl_Invoices[[#This Row],[Customer_ID]], tbl_Customers[Customer_ID], tbl_Customers[Region]) -> Midwest | N6: {=_xlfn.IFS( _xlfn.SINGLE(tbl_Invoices[Plan_ID])="P1","Basic", _xlfn.SINGLE(tbl_Invoices[Plan_ID])="P2","Standard", _xlfn.SINGLE(tbl_Invoices[Plan_ID])="P3","Premium" )} -> Standard | O6: =IF(tbl_Invoices[[#This Row],[Revenue_Type]]="Churned",0,1) -> 1
A7: I004096 | B7: C0063 | C7: S01614 | D7: 44198 | E7: 12 | F7: TRUE | G7: Churned | H7: P1 | I7: =DATE(YEAR(tbl_Invoices[[#This Row],[Invoice_Date]]), MONTH(tbl_Invoices[[#This Row],[Invoice_Date]]), DAY(tbl_Invoices[[#This Row],[Invoice_Date]])) -> 44198 | J7: =YEAR(tbl_Invoices[[#This Row],[Invoice_Date]]) -> 2021 | K7: =_xlfn.XLOOKUP(tbl_Invoices[[#This Row],[Customer_ID]], tbl_Customers[Customer_ID], tbl_Customers[Cohort_Month]) -> 44773 | L7: =_xlfn.XLOOKUP(tbl_Invoices[[#This Row],[Customer_ID]], tbl_Customers[Customer_ID], tbl_Customers[Age_Group]) -> 45–54 | M7: =_xlfn.XLOOKUP(tbl_Invoices[[#This Row],[Customer_ID]], tbl_Customers[Customer_ID], tbl_Customers[Region]) -> West | N7: {=_xlfn.IFS( _xlfn.SINGLE(tbl_Invoices[Plan_ID])="P1","Basic", _xlfn.SINGLE(tbl_Invoices[Plan_ID])="P2","Standard", _xlfn.SINGLE(tbl_Invoices[Plan_ID])="P3","Premium" )} -> Basic | O7: =IF(tbl_Invoices[[#This Row],[Revenue_Type]]="Churned",0,1) -> 0
A8: I002939 | B8: C0202 | C8: S00922 | D8: 44198 | E8: 12 | F8: TRUE | G8: New | H8: P1 | I8: =DATE(YEAR(tbl_Invoices[[#This Row],[Invoice_Date]]), MONTH(tbl_Invoices[[#This Row],[Invoice_Date]]), DAY(tbl_Invoices[[#This Row],[Invoice_Date]])) -> 44198 | J8: =YEAR(tbl_Invoices[[#This Row],[Invoice_Date]]) -> 2021 | K8: =_xlfn.XLOOKUP(tbl_Invoices[[#This Row],[Customer_ID]], tbl_Customers[Customer_ID], tbl_Customers[Cohort_Month]) -> 44469 | L8: =_xlfn.XLOOKUP(tbl_Invoices[[#This Row],[Customer_ID]], tbl_Customers[Customer_ID], tbl_Customers[Age_Group]) -> 45–54 | M8: =_xlfn.XLOOKUP(tbl_Invoices[[#This Row],[Customer_ID]], tbl_Customers[Customer_ID], tbl_Customers[Region]) -> International | N8: {=_xlfn.IFS( _xlfn.SINGLE(tbl_Invoices[Plan_ID])="P1","Basic", _xlfn.SINGLE(tbl_Invoices[Plan_ID])="P2","Standard", _xlfn.SINGLE(tbl_Invoices[Plan_ID])="P3","Premium" )} -> Basic | O8: =IF(tbl_Invoices[[#This Row],[Revenue_Type]]="Churned",0,1) -> 1
A9: I002668 | B9: C0409 | C9: S00188 | D9: 44198 | E9: 12 | F9: TRUE | G9: Renewal | H9: P1 | I9: =DATE(YEAR(tbl_Invoices[[#This Row],[Invoice_Date]]), MONTH(tbl_Invoices[[#This Row],[Invoice_Date]]), DAY(tbl_Invoices[[#This Row],[Invoice_Date]])) -> 44198 | J9: =YEAR(tbl_Invoices[[#This Row],[Invoice_Date]]) -> 2021 | K9: =_xlfn.XLOOKUP(tbl_Invoices[[#This Row],[Customer_ID]], tbl_Customers[Customer_ID], tbl_Customers[Cohort_Month]) -> 44742 | L9: =_xlfn.XLOOKUP(tbl_Invoices[[#This Row],[Customer_ID]], tbl_Customers[Customer_ID], tbl_Customers[Age_Group]) -> 25–34 | M9: =_xlfn.XLOOKUP(tbl_Invoices[[#This Row],[Customer_ID]], tbl_Customers[Customer_ID], tbl_Customers[Region]) -> International | N9: {=_xlfn.IFS( _xlfn.SINGLE(tbl_Invoices[Plan_ID])="P1","Basic", _xlfn.SINGLE(tbl_Invoices[Plan_ID])="P2","Standard", _xlfn.SINGLE(tbl_Invoices[Plan_ID])="P3","Premium" )} -> Basic | O9: =IF(tbl_Invoices[[#This Row],[Revenue_Type]]="Churned",0,1) -> 1
A10: I003924 | B10: C0450 | C10: S01598 | D10: 44198 | E10: 25 | F10: TRUE | G10: Renewal | H10: P2 | I10: =DATE(YEAR(tbl_Invoices[[#This Row],[Invoice_Date]]), MONTH(tbl_Invoices[[#This Row],[Invoice_Date]]), DAY(tbl_Invoices[[#This Row],[Invoice_Date]])) -> 44198 | J10: =YEAR(tbl_Invoices[[#This Row],[Invoice_Date]]) -> 2021 | K10: =_xlfn.XLOOKUP(tbl_Invoices[[#This Row],[Customer_ID]], tbl_Customers[Customer_ID], tbl_Customers[Cohort_Month]) -> 44227 | L10: =_xlfn.XLOOKUP(tbl_Invoices[[#This Row],[Customer_ID]], tbl_Customers[Customer_ID], tbl_Customers[Age_Group]) -> 35–44 | M10: =_xlfn.XLOOKUP(tbl_Invoices[[#This Row],[Customer_ID]], tbl_Customers[Customer_ID], tbl_Customers[Region]) -> International | N10: {=_xlfn.IFS( _xlfn.SINGLE(tbl_Invoices[Plan_ID])="P1","Basic", _xlfn.SINGLE(tbl_Invoices[Plan_ID])="P2","Standard", _xlfn.SINGLE(tbl_Invoices[Plan_ID])="P3","Premium" )} -> Standard | O10: =IF(tbl_Invoices[[#This Row],[Revenue_Type]]="Churned",0,1) -> 1
A11: I001243 | B11: C0677 | C11: S02081 | D11: 44198 | E11: 55 | F11: TRUE | G11: Renewal | H11: P3 | I11: =DATE(YEAR(tbl_Invoices[[#This Row],[Invoice_Date]]), MONTH(tbl_Invoices[[#This Row],[Invoice_Date]]), DAY(tbl_Invoices[[#This Row],[Invoice_Date]])) -> 44198 | J11: =YEAR(tbl_Invoices[[#This Row],[Invoice_Date]]) -> 2021 | K11: =_xlfn.XLOOKUP(tbl_Invoices[[#This Row],[Customer_ID]], tbl_Customers[Customer_ID], tbl_Customers[Cohort_Month]) -> 44408 | L11: =_xlfn.XLOOKUP(tbl_Invoices[[#This Row],[Customer_ID]], tbl_Customers[Customer_ID], tbl_Customers[Age_Group]) -> 25–34 | M11: =_xlfn.XLOOKUP(tbl_Invoices[[#This Row],[Customer_ID]], tbl_Customers[Customer_ID], tbl_Customers[Region]) -> South | N11: {=_xlfn.IFS( _xlfn.SINGLE(tbl_Invoices[Plan_ID])="P1","Basic", _xlfn.SINGLE(tbl_Invoices[Plan_ID])="P2","Standard", _xlfn.SINGLE(tbl_Invoices[Plan_ID])="P3","Premium" )} -> Premium | O11: =IF(tbl_Invoices[[#This Row],[Revenue_Type]]="Churned",0,1) -> 1
A12: I005538 | B12: C1357 | C12: S00475 | D12: 44198 | E12: 25 | F12: TRUE | G12: Churned | H12: P2 | I12: =DATE(YEAR(tbl_Invoices[[#This Row],[Invoice_Date]]), MONTH(tbl_Invoices[[#This Row],[Invoice_Date]]), DAY(tbl_Invoices[[#This Row],[Invoice_Date]])) -> 44198 | J12: =YEAR(tbl_Invoices[[#This Row],[Invoice_Date]]) -> 2021 | K12: =_xlfn.XLOOKUP(tbl_Invoices[[#This Row],[Customer_ID]], tbl_Customers[Customer_ID], tbl_Customers[Cohort_Month]) -> 44926 | L12: =_xlfn.XLOOKUP(tbl_Invoices[[#This Row],[Customer_ID]], tbl_Customers[Customer_ID], tbl_Customers[Age_Group]) -> 55+ | M12: =_xlfn.XLOOKUP(tbl_Invoices[[#This Row],[Customer_ID]], tbl_Customers[Customer_ID], tbl_Customers[Region]) -> Midwest | N12: {=_xlfn.IFS( _xlfn.SINGLE(tbl_Invoices[Plan_ID])="P1","Basic", _xlfn.SINGLE(tbl_Invoices[Plan_ID])="P2","Standard", _xlfn.SINGLE(tbl_Invoices[Plan_ID])="P3","Premium" )} -> Standard | O12: =IF(tbl_Invoices[[#This Row],[Revenue_Type]]="Churned",0,1) -> 0
A13: I004228 | B13: C0367 | C13: S00196 | D13: 44199 | E13: 12 | F13: TRUE | G13: Expansion | H13: P1 | I13: =DATE(YEAR(tbl_Invoices[[#This Row],[Invoice_Date]]), MONTH(tbl_Invoices[[#This Row],[Invoice_Date]]), DAY(tbl_Invoices[[#This Row],[Invoice_Date]])) -> 44199 | J13: =YEAR(tbl_Invoices[[#This Row],[Invoice_Date]]) -> 2021 | K13: =_xlfn.XLOOKUP(tbl_Invoices[[#This Row],[Customer_ID]], tbl_Customers[Customer_ID], tbl_Customers[Cohort_Month]) -> 44712 | L13: =_xlfn.XLOOKUP(tbl_Invoices[[#This Row],[Customer_ID]], tbl_Customers[Customer_ID], tbl_Customers[Age_Group]) -> 25–34 | M13: =_xlfn.XLOOKUP(tbl_Invoices[[#This Row],[Customer_ID]], tbl_Customers[Customer_ID], tbl_Customers[Region]) -> Midwest | N13: {=_xlfn.IFS( _xlfn.SINGLE(tbl_Invoices[Plan_ID])="P1","Basic", _xlfn.SINGLE(tbl_Invoices[Plan_ID])="P2","Standard", _xlfn.SINGLE(tbl_Invoices[Plan_ID])="P3","Premium" )} -> Basic | O13: =IF(tbl_Invoices[[#This Row],[Revenue_Type]]="Churned",0,1) -> 1
... A6001: I002106 | B6001: C1893 | C6001: S00253 | D6001: 45097 | E6001: 55 | F6001: TRUE | G6001: New | H6001: P3 | I6001: =DATE(YEAR(tbl_Invoices[[#This Row],[Invoice_Date]]), MONTH(tbl_Invoices[[#This Row],[Invoice_Date]]), DAY(tbl_Invoices[[#This Row],[Invoice_Date]])) -> 45097 | J6001: =YEAR(tbl_Invoices[[#This Row],[Invoice_Date]]) -> 2023 | K6001: =_xlfn.XLOOKUP(tbl_Invoices[[#This Row],[Customer_ID]], tbl_Customers[Customer_ID], tbl_Customers[Cohort_Month]) -> 45077 | L6001: =_xlfn.XLOOKUP(tbl_Invoices[[#This Row],[Customer_ID]], tbl_Customers[Customer_ID], tbl_Customers[Age_Group]) -> 45–54 | M6001: =_xlfn.XLOOKUP(tbl_Invoices[[#This Row],[Customer_ID]], tbl_Customers[Customer_ID], tbl_Customers[Region]) -> International | N6001: {=_xlfn.IFS( _xlfn.SINGLE(tbl_Invoices[Plan_ID])="P1","Basic", _xlfn.SINGLE(tbl_Invoices[Plan_ID])="P2","Standard", _xlfn.SINGLE(tbl_Invoices[Plan_ID])="P3","Premium" )} -> Premium | O6001: =IF(tbl_Invoices[[#This Row],[Revenue_Type]]="Churned",0,1) -> 1

Sheet Marketing
A1: Month | B1: Channel | C1: Spend | D1: New_Customers
A2: 44227 | B2: Paid Ads | C2: 11608 | D2: 69
A3: 44227 | B3: Organic Search | C3: 0 | D3: 104
A4: 44227 | B4: Social Media | C4: 10795 | D4: 72
A5: 44227 | B5: Affiliate | C5: 4247 | D5: 21
A6: 44227 | B6: Referral | C6: 11432 | D6: 46
A7: 44255 | B7: Paid Ads | C7: 9647 | D7: 79
A8: 44255 | B8: Organic Search | C8: 0 | D8: 49
A9: 44255 | B9: Social Media | C9: 9576 | D9: 84
A10: 44255 | B10: Affiliate | C10: 13596 | D10: 56
A11: 44255 | B11: Referral | C11: 1107 | D11: 10
A12: 44286 | B12: Paid Ads | C12: 483 | D12: 114
A13: 44286 | B13: Organic Search | C13: 0 | D13: 98
... A181: 45291 | B181: Referral | C181: 2125 | D181: 82

Sheet Parameters

Sheet Monthly_KPIs

Sheet Cohorts

Sheet Segmentation
